Workbook

Sheet Setup
A1: ⚙️ SETUP — Accounts, Cards & Reference Lists
A3: 💰 INCOME SOURCES | D3: 💳 CREDIT CARDS
A4: Account / Source Name | B4: Monthly Amount (₹) | D4: Card Name | E4: Credit Limit (₹) | F4: Opening Dues (₹)
A5: Salary
A11: 🏦 SAVINGS ACCOUNTS | D11: 📋 CATEGORY → SUB-CATEGORY REFERENCE
A12: Account Name | B12: Opening Balance (₹) | D12: Category | F12: Sub-Categories
D13: Fixed Bills | F13: Rent / Home Loan EMI / Electricity / Internet / WiFi / Mobile Recharge / OTT Subscriptions / Insurance Premium / Gym / Fitness / Other Bill
D14: Food & Dining | F14: Restaurants / Swiggy / Zomato / Cafes / Street Food / Other
D15: Transport & Fuel | F15: Fuel / Auto / Cab / Metro / Bus / Parking / Vehicle Maintenance / Other
D16: Shopping & Clothing | F16: Clothing / Electronics / Home & Decor / Online Shopping / Other
D17: Entertainment & OTT | F17: Movies / Events / OTT Subscriptions / Gaming / Other
D18: Groceries | F18: Vegetables & Fruits / Dairy / Supermarket / Kirana Store / Other
D19: Investment | F19: SIP / Mutual Funds / Fixed Deposit / Gold / Others / Stocks / PPF / NPS / Other Investment
D20: Added to Savings | F20: (your savings account names)
D21: Credit Card Payment | F21: Full Payment / Minimum Due / Partial Payment
D22: Miscellaneous | F22: Medical / Education / Gifts / Charity / Other

Sheet Income
A1: 💰 INCOME TRACKER — Enter salary once in Setup; log extra income per month here
A3: Month | B3: Salary (₹) | C3: Extra Income (₹) | D3: Notes | E3: Total Income (₹)
A4: April | B4: =Setup!B5 | E4: =B4+C4
A5: May | B5: =Setup!B5 | E5: =B5+C5
A6: June | B6: =Setup!B5 | E6: =B6+C6
A7: July | B7: =Setup!B5 | E7: =B7+C7
A8: August | B8: =Setup!B5 | E8: =B8+C8
A9: September | B9: =Setup!B5 | E9: =B9+C9
A10: October | B10: =Setup!B5 | E10: =B10+C10
A11: November | B11: =Setup!B5 | E11: =B11+C11
A12: December | B12: =Setup!B5 | E12: =B12+C12
A13: January | B13: =Setup!B5 | E13: =B13+C13
A14: February | B14: =Setup!B5 | E14: =B14+C14
A15: March | B15: =Setup!B5 | E15: =B15+C15
A16: ANNUAL TOTAL | B16: =SUM(B4:B15) | C16: =SUM(C4:C15) | E16: =SUM(E4:E15)

Sheet April
A1: 📝 APRIL — EXPENSE LOG
A2: ℹ️ Date is DateTime. Category dropdown → Sub-category changes automatically. 'Added to Savings' → pick your saving account in Sub-category. CC spend → pick card in 'CC Name'. CC payment → increases card limit.
A4: # | B4: Date & Time | C4: Description | D4: Category | E4: Sub-category | F4: Amount (₹) | G4: Paid From | H4: CC Name | I4: Account | J4: Notes | L4: 📊 April Summary | M4: Amount (₹)
A5: =IF(F5<>"",ROW()-4,"") | L5: Total Expenses | M5: =F256
A6: =IF(F6<>"",ROW()-4,"") | L6: Income This Month | M6: =Income!E4
A7: =IF(F7<>"",ROW()-4,"") | L7: Net This Month | M7: =M6-M5
A8: =IF(F8<>"",ROW()-4,"") | L8: Savings 1 (this month) | M8: =IF(Setup!A13<>"",SUMIFS(F5:F255,D5:D255,"Added to Savings",I5:I255,Setup!A13)-SUMIFS(F5:F255,G5:G255,Setup!A13),"")
A9: =IF(F9<>"",ROW()-4,"") | L9: Savings 1 (balance) | M9: =IF(Setup!A13<>"",Setup!B13+(SUMIFS('April'!F5:F64,'April'!D5:D64,"Added to Savings",'April'!I5:I64,Setup!A13))-(SUMIFS('April'!F5:F64,'April'!G5:G64,Setup!A13)),"")
A10: =IF(F10<>"",ROW()-4,"") | L10: Savings 2 (this month) | M10: =IF(Setup!A14<>"",SUMIFS(F5:F255,D5:D255,"Added to Savings",I5:I255,Setup!A14)-SUMIFS(F5:F255,G5:G255,Setup!A14),"")
A11: =IF(F11<>"",ROW()-4,"") | L11: Savings 2 (balance) | M11: =IF(Setup!A14<>"",Setup!B14+(SUMIFS('April'!F5:F64,'April'!D5:D64,"Added to Savings",'April'!I5:I64,Setup!A14))-(SUMIFS('April'!F5:F64,'April'!G5:G64,Setup!A14)),"")
A12: =IF(F12<>"",ROW()-4,"") | L12: Savings 3 (this month) | M12: =IF(Setup!A15<>"",SUMIFS(F5:F255,D5:D255,"Added to Savings",I5:I255,Setup!A15)-SUMIFS(F5:F255,G5:G255,Setup!A15),"")
A13: =IF(F13<>"",ROW()-4,"") | L13: Savings 3 (balance) | M13: =IF(Setup!A15<>"",Setup!B15+(SUMIFS('April'!F5:F64,'April'!D5:D64,"Added to Savings",'April'!I5:I64,Setup!A15))-(SUMIFS('April'!F5:F64,'April'!G5:G64,Setup!A15)),"")
A14: =IF(F14<>"",ROW()-4,"") | L14: Savings 4 (this month) | M14: =IF(Setup!A16<>"",SUMIFS(F5:F255,D5:D255,"Added to Savings",I5:I255,Setup!A16)-SUMIFS(F5:F255,G5:G255,Setup!A16),"")
A15: =IF(F15<>"",ROW()-4,"") | L15: Savings 4 (balance) | M15: =IF(Setup!A16<>"",Setup!B16+(SUMIFS('April'!F5:F64,'April'!D5:D64,"Added to Savings",'April'!I5:I64,Setup!A16))-(SUMIFS('April'!F5:F64,'April'!G5:G64,Setup!A16)),"")
A16: =IF(F16<>"",ROW()-4,"") | L16: Savings 5 (this month) | M16: =IF(Setup!A17<>"",SUMIFS(F5:F255,D5:D255,"Added to Savings",I5:I255,Setup!A17)-SUMIFS(F5:F255,G5:G255,Setup!A17),"")
A17: =IF(F17<>"",ROW()-4,"") | L17: Savings 5 (balance) | M17: =IF(Setup!A17<>"",Setup!B17+(SUMIFS('April'!F5:F64,'April'!D5:D64,"Added to Savings",'April'!I5:I64,Setup!A17))-(SUMIFS('April'!F5:F64,'April'!G5:G64,Setup!A17)),"")
A18: =IF(F18<>"",ROW()-4,"") | L18: Fixed Bills Paid | M18: =SUMIF(D5:D255,"Fixed Bills",F5:F255)
A19: =IF(F19<>"",ROW()-4,"") | L19: Food & Dining | M19: =SUMIF(D5:D255,"Food & Dining",F5:F255)
A20: =IF(F20<>"",ROW()-4,"") | L20: Transport | M20: =SUMIF(D5:D255,"Transport & Fuel",F5:F255)
A21: =IF(F21<>"",ROW()-4,"") | L21: Groceries | M21: =SUMIF(D5:D255,"Groceries",F5:F255)
A22: =IF(F22<>"",ROW()-4,"") | L22: Shopping | M22: =SUMIF(D5:D255,"Shopping & Clothing",F5:F255)
A23: =IF(F23<>"",ROW()-4,"") | L23: Entertainment | M23: =SUMIF(D5:D255,"Entertainment & OTT",F5:F255)
A24: =IF(F24<>"",ROW()-4,"") | L24: Investment | M24: =SUMIF(D5:D255,"Investment",F5:F255)
A25: =IF(F25<>"",ROW()-4,"") | L25: Added to Savings | M25: =SUMIF(D5:D255,"Added to Savings",F5:F255)
A26: =IF(F26<>"",ROW()-4,"") | L26: CC Payments | M26: =SUMIF(D5:D255,"Credit Card Payment",F5:F255)
A27: =IF(F27<>"",ROW()-4,"") | L27: Miscellaneous | M27: =SUMIF(D5:D255,"Miscellaneous",F5:F255)
A28: =IF(F28<>"",ROW()-4,"")
A29: =IF(F29<>"",ROW()-4,"")
A30: =IF(F30<>"",ROW()-4,"")
A31: =IF(F31<>"",ROW()-4,"")
A32: =IF(F32<>"",ROW()-4,"")
A33: =IF(F33<>"",ROW()-4,"")
A34: =IF(F34<>"",ROW()-4,"")
A35: =IF(F35<>"",ROW()-4,"")
A36: =IF(F36<>"",ROW()-4,"")
A37: =IF(F37<>"",ROW()-4,"")
A38: =IF(F38<>"",ROW()-4,"")
A39: =IF(F39<>"",ROW()-4,"")
... A255: =IF(F255<>"",ROW()-4,"")
A256: TOTAL EXPENSES THIS MONTH | F256: =SUM(F5:F255)

Sheet May
A1: 📝 MAY — EXPENSE LOG
A2: ℹ️ Date is DateTime. Category dropdown → Sub-category changes automatically. 'Added to Savings' → pick your saving account in Sub-category. CC spend → pick card in 'CC Name'. CC payment → increases card limit.
A4: # | B4: Date & Time | C4: Description | D4: Category | E4: Sub-category | F4: Amount (₹) | G4: Paid From | H4: CC Name | I4: Account | J4: Notes | L4: 📊 May Summary | M4: Amount (₹)
A5: =IF(F5<>"",ROW()-4,"") | L5: Total Expenses | M5: =F256
A6: =IF(F6<>"",ROW()-4,"") | L6: Income This Month | M6: =Income!E5
A7: =IF(F7<>"",ROW()-4,"") | L7: Net This Month | M7: =M6-M5
A8: =IF(F8<>"",ROW()-4,"") | L8: Savings 1 (this month) | M8: =IF(Setup!A13<>"",SUMIFS(F5:F255,D5:D255,"Added to Savings",I5:I255,Setup!A13)-SUMIFS(F5:F255,G5:G255,Setup!A13),"")
A9: =IF(F9<>"",ROW()-4,"") | L9: Savings 1 (balance) | M9: =IF(Setup!A13<>"",Setup!B13+(SUMIFS('April'!F5:F64,'April'!D5:D64,"Added to Savings",'April'!I5:I64,Setup!A13)+SUMIFS('May'!F5:F64,'May'!D5:D64,"Added to Savings",'May'!I5:I64,Setup!A13))-(SUMIFS('April'!F5:F64,'April'!G5:G64,Setup!A13)+SUMIFS('May'!F5:F64,'May'!G5:G64,Setup!A13)),"")
A10: =IF(F10<>"",ROW()-4,"") | L10: Savings 2 (this month) | M10: =IF(Setup!A14<>"",SUMIFS(F5:F255,D5:D255,"Added to Savings",I5:I255,Setup!A14)-SUMIFS(F5:F255,G5:G255,Setup!A14),"")
A11: =IF(F11<>"",ROW()-4,"") | L11: Savings 2 (balance) | M11: =IF(Setup!A14<>"",Setup!B14+(SUMIFS('April'!F5:F64,'April'!D5:D64,"Added to Savings",'April'!I5:I64,Setup!A14)+SUMIFS('May'!F5:F64,'May'!D5:D64,"Added to Savings",'May'!I5:I64,Setup!A14))-(SUMIFS('April'!F5:F64,'April'!G5:G64,Setup!A14)+SUMIFS('May'!F5:F64,'May'!G5:G64,Setup!A14)),"")
A12: =IF(F12<>"",ROW()-4,"") | L12: Savings 3 (this month) | M12: =IF(Setup!A15<>"",SUMIFS(F5:F255,D5:D255,"Added to Savings",I5:I255,Setup!A15)-SUMIFS(F5:F255,G5:G255,Setup!A15),"")
A13: =IF(F13<>"",ROW()-4,"") | L13: Savings 3 (balance) | M13: =IF(Setup!A15<>"",Setup!B15+(SUMIFS('April'!F5:F64,'April'!D5:D64,"Added to Savings",'April'!I5:I64,Setup!A15)+SUMIFS('May'!F5:F64,'May'!D5:D64,"Added to Savings",'May'!I5:I64,Setup!A15))-(SUMIFS('April'!F5:F64,'April'!G5:G64,Setup!A15)+SUMIFS('May'!F5:F64,'May'!G5:G64,Setup!A15)),"")
A14: =IF(F14<>"",ROW()-4,"") | L14: Savings 4 (this month) | M14: =IF(Setup!A16<>"",SUMIFS(F5:F255,D5:D255,"Added to Savings",I5:I255,Setup!A16)-SUMIFS(F5:F255,G5:G255,Setup!A16),"")
A15: =IF(F15<>"",ROW()-4,"") | L15: Savings 4 (balance) | M15: =IF(Setup!A16<>"",Setup!B16+(SUMIFS('April'!F5:F64,'April'!D5:D64,"Added to Savings",'April'!I5:I64,Setup!A16)+SUMIFS('May'!F5:F64,'May'!D5:D64,"Added to Savings",'May'!I5:I64,Setup!A16))-(SUMIFS('April'!F5:F64,'April'!G5:G64,Setup!A16)+SUMIFS('May'!F5:F64,'May'!G5:G64,Setup!A16)),"")
A16: =IF(F16<>"",ROW()-4,"") | L16: Savings 5 (this month) | M16: =IF(Setup!A17<>"",SUMIFS(F5:F255,D5:D255,"Added to Savings",I5:I255,Setup!A17)-SUMIFS(F5:F255,G5:G255,Setup!A17),"")
A17: =IF(F17<>"",ROW()-4,"") | L17: Savings 5 (balance) | M17: =IF(Setup!A17<>"",Setup!B17+(SUMIFS('April'!F5:F64,'April'!D5:D64,"Added to Savings",'April'!I5:I64,Setup!A17)+SUMIFS('May'!F5:F64,'May'!D5:D64,"Added to Savings",'May'!I5:I64,Setup!A17))-(SUMIFS('April'!F5:F64,'April'!G5:G64,Setup!A17)+SUMIFS('May'!F5:F64,'May'!G5:G64,Setup!A17)),"")
A18: =IF(F18<>"",ROW()-4,"") | L18: Fixed Bills Paid | M18: =SUMIF(D5:D255,"Fixed Bills",F5:F255)
A19: =IF(F19<>"",ROW()-4,"") | L19: Food & Dining | M19: =SUMIF(D5:D255,"Food & Dining",F5:F255)
A20: =IF(F20<>"",ROW()-4,"") | L20: Transport | M20: =SUMIF(D5:D255,"Transport & Fuel",F5:F255)
A21: =IF(F21<>"",ROW()-4,"") | L21: Groceries | M21: =SUMIF(D5:D255,"Groceries",F5:F255)
A22: =IF(F22<>"",ROW()-4,"") | L22: Shopping | M22: =SUMIF(D5:D255,"Shopping & Clothing",F5:F255)
A23: =IF(F23<>"",ROW()-4,"") | L23: Entertainment | M23: =SUMIF(D5:D255,"Entertainment & OTT",F5:F255)
A24: =IF(F24<>"",ROW()-4,"") | L24: Investment | M24: =SUMIF(D5:D255,"Investment",F5:F255)
A25: =IF(F25<>"",ROW()-4,"") | L25: Added to Savings | M25: =SUMIF(D5:D255,"Added to Savings",F5:F255)
A26: =IF(F26<>"",ROW()-4,"") | L26: CC Payments | M26: =SUMIF(D5:D255,"Credit Card Payment",F5:F255)
A27: =IF(F27<>"",ROW()-4,"") | L27: Miscellaneous | M27: =SUMIF(D5:D255,"Miscellaneous",F5:F255)
A28: =IF(F28<>"",ROW()-4,"")
A29: =IF(F29<>"",ROW()-4,"")
A30: =IF(F30<>"",ROW()-4,"")
A31: =IF(F31<>"",ROW()-4,"")
A32: =IF(F32<>"",ROW()-4,"")
A33: =IF(F33<>"",ROW()-4,"")
A34: =IF(F34<>"",ROW()-4,"")
A35: =IF(F35<>"",ROW()-4,"")
A36: =IF(F36<>"",ROW()-4,"")
A37: =IF(F37<>"",ROW()-4,"")
A38: =IF(F38<>"",ROW()-4,"")
A39: =IF(F39<>"",ROW()-4,"")
... A255: =IF(F255<>"",ROW()-4,"")
A256: TOTAL EXPENSES THIS MONTH | F256: =SUM(F5:F255)

Sheet June
A1: 📝 JUNE — EXPENSE LOG
A2: ℹ️ Date is DateTime. Category dropdown → Sub-category changes automatically. 'Added to Savings' → pick your saving account in Sub-category. CC spend → pick card in 'CC Name'. CC payment → increases card limit.
A4: # | B4: Date & Time | C4: Description | D4: Category | E4: Sub-category | F4: Amount (₹) | G4: Paid From | H4: CC Name | I4: Account | J4: Notes | L4: 📊 June Summary | M4: Amount (₹)
A5: =IF(F5<>"",ROW()-4,"") | L5: Total Expenses | M5: =F256
A6: =IF(F6<>"",ROW()-4,"") | L6: Income This Month | M6: =Income!E6
A7: =IF(F7<>"",ROW()-4,"") | L7: Net This Month | M7: =M6-M5
A8: =IF(F8<>"",ROW()-4,"") | L8: Savings 1 (this month) | M8: =IF(Setup!A13<>"",SUMIFS(F5:F255,D5:D255,"Added to Savings",I5:I255,Setup!A13)-SUMIFS(F5:F255,G5:G255,Setup!A13),"")
A9: =IF(F9<>"",ROW()-4,"") | L9: Savings 1 (balance) | M9: =IF(Setup!A13<>"",Setup!B13+(SUMIFS('April'!F5:F64,'April'!D5:D64,"Added to Savings",'April'!I5:I64,Setup!A13)+SUMIFS('May'!F5:F64,'May'!D5:D64,"Added to Savings",'May'!I5:I64,Setup!A13)+SUMIFS('June'!F5:F64,'June'!D5:D64,"Added to Savings",'June'!I5:I64,Setup!A13))-(SUMIFS('April'!F5:F64,'April'!G5:G64,Setup!A13)+SUMIFS('May'!F5:F64,'May'!G5:G64,Setup!A13)+SUMIFS('June'!F5:F64,'June'!G5:G64,Setup!A13)),"")
A10: =IF(F10<>"",ROW()-4,"") | L10: Savings 2 (this month) | M10: =IF(Setup!A14<>"",SUMIFS(F5:F255,D5:D255,"Added to Savings",I5:I255,Setup!A14)-SUMIFS(F5:F255,G5:G255,Setup!A14),"")
A11: =IF(F11<>"",ROW()-4,"") | L11: Savings 2 (balance) | M11: =IF(Setup!A14<>"",Setup!B14+(SUMIFS('April'!F5:F64,'April'!D5:D64,"Added to Savings",'April'!I5:I64,Setup!A14)+SUMIFS('May'!F5:F64,'May'!D5:D64,"Added to Savings",'May'!I5:I64,Setup!A14)+SUMIFS('June'!F5:F64,'June'!D5:D64,"Added to Savings",'June'!I5:I64,Setup!A14))-(SUMIFS('April'!F5:F64,'April'!G5:G64,Setup!A14)+SUMIFS('May'!F5:F64,'May'!G5:G64,Setup!A14)+SUMIFS('June'!F5:F64,'June'!G5:G64,Setup!A14)),"")
A12: =IF(F12<>"",ROW()-4,"") | L12: Savings 3 (this month) | M12: =IF(Setup!A15<>"",SUMIFS(F5:F255,D5:D255,"Added to Savings",I5:I255,Setup!A15)-SUMIFS(F5:F255,G5:G255,Setup!A15),"")
A13: =IF(F13<>"",ROW()-4,"") | L13: Savings 3 (balance) | M13: =IF(Setup!A15<>"",Setup!B15+(SUMIFS('April'!F5:F64,'April'!D5:D64,"Added to Savings",'April'!I5:I64,Setup!A15)+SUMIFS('May'!F5:F64,'May'!D5:D64,"Added to Savings",'May'!I5:I64,Setup!A15)+SUMIFS('June'!F5:F64,'June'!D5:D64,"Added to Savings",'June'!I5:I64,Setup!A15))-(SUMIFS('April'!F5:F64,'April'!G5:G64,Setup!A15)+SUMIFS('May'!F5:F64,'May'!G5:G64,Setup!A15)+SUMIFS('June'!F5:F64,'June'!G5:G64,Setup!A15)),"")
A14: =IF(F14<>"",ROW()-4,"") | L14: Savings 4 (this month) | M14: =IF(Setup!A16<>"",SUMIFS(F5:F255,D5:D255,"Added to Savings",I5:I255,Setup!A16)-SUMIFS(F5:F255,G5:G255,Setup!A16),"")
A15: =IF(F15<>"",ROW()-4,"") | L15: Savings 4 (balance) | M15: =IF(Setup!A16<>"",Setup!B16+(SUMIFS('April'!F5:F64,'April'!D5:D64,"Added to Savings",'April'!I5:I64,Setup!A16)+SUMIFS('May'!F5:F64,'May'!D5:D64,"Added to Savings",'May'!I5:I64,Setup!A16)+SUMIFS('June'!F5:F64,'June'!D5:D64,"Added to Savings",'June'!I5:I64,Setup!A16))-(SUMIFS('April'!F5:F64,'April'!G5:G64,Setup!A16)+SUMIFS('May'!F5:F64,'May'!G5:G64,Setup!A16)+SUMIFS('June'!F5:F64,'June'!G5:G64,Setup!A16)),"")
A16: =IF(F16<>"",ROW()-4,"") | L16: Savings 5 (this month) | M16: =IF(Setup!A17<>"",SUMIFS(F5:F255,D5:D255,"Added to Savings",I5:I255,Setup!A17)-SUMIFS(F5:F255,G5:G255,Setup!A17),"")
A17: =IF(F17<>"",ROW()-4,"") | L17: Savings 5 (balance) | M17: =IF(Setup!A17<>"",Setup!B17+(SUMIFS('April'!F5:F64,'April'!D5:D64,"Added to Savings",'April'!I5:I64,Setup!A17)+SUMIFS('May'!F5:F64,'May'!D5:D64,"Added to Savings",'May'!I5:I64,Setup!A17)+SUMIFS('June'!F5:F64,'June'!D5:D64,"Added to Savings",'June'!I5:I64,Setup!A17))-(SUMIFS('April'!F5:F64,'April'!G5:G64,Setup!A17)+SUMIFS('May'!F5:F64,'May'!G5:G64,Setup!A17)+SUMIFS('June'!F5:F64,'June'!G5:G64,Setup!A17)),"")
A18: =IF(F18<>"",ROW()-4,"") | L18: Fixed Bills Paid | M18: =SUMIF(D5:D255,"Fixed Bills",F5:F255)
A19: =IF(F19<>"",ROW()-4,"") | L19: Food & Dining | M19: =SUMIF(D5:D255,"Food & Dining",F5:F255)
A20: =IF(F20<>"",ROW()-4,"") | L20: Transport | M20: =SUMIF(D5:D255,"Transport & Fuel",F5:F255)
A21: =IF(F21<>"",ROW()-4,"") | L21: Groceries | M21: =SUMIF(D5:D255,"Groceries",F5:F255)
A22: =IF(F22<>"",ROW()-4,"") | L22: Shopping | M22: =SUMIF(D5:D255,"Shopping & Clothing",F5:F255)
A23: =IF(F23<>"",ROW()-4,"") | L23: Entertainment | M23: =SUMIF(D5:D255,"Entertainment & OTT",F5:F255)
A24: =IF(F24<>"",ROW()-4,"") | L24: Investment | M24: =SUMIF(D5:D255,"Investment",F5:F255)
A25: =IF(F25<>"",ROW()-4,"") | L25: Added to Savings | M25: =SUMIF(D5:D255,"Added to Savings",F5:F255)
A26: =IF(F26<>"",ROW()-4,"") | L26: CC Payments | M26: =SUMIF(D5:D255,"Credit Card Payment",F5:F255)
A27: =IF(F27<>"",ROW()-4,"") | L27: Miscellaneous | M27: =SUMIF(D5:D255,"Miscellaneous",F5:F255)
A28: =IF(F28<>"",ROW()-4,"")
A29: =IF(F29<>"",ROW()-4,"")
A30: =IF(F30<>"",ROW()-4,"")
A31: =IF(F31<>"",ROW()-4,"")
A32: =IF(F32<>"",ROW()-4,"")
A33: =IF(F33<>"",ROW()-4,"")
A34: =IF(F34<>"",ROW()-4,"")
A35: =IF(F35<>"",ROW()-4,"")
A36: =IF(F36<>"",ROW()-4,"")
A37: =IF(F37<>"",ROW()-4,"")
A38: =IF(F38<>"",ROW()-4,"")
A39: =IF(F39<>"",ROW()-4,"")
... A255: =IF(F255<>"",ROW()-4,"")
A256: TOTAL EXPENSES THIS MONTH | F256: =SUM(F5:F255)

Sheet July
A1: 📝 JULY — EXPENSE LOG
A2: ℹ️ Date is DateTime. Category dropdown → Sub-category changes automatically. 'Added to Savings' → pick your saving account in Sub-category. CC spend → pick card in 'CC Name'. CC payment → increases card limit.
A4: # | B4: Date & Time | C4: Description | D4: Category | E4: Sub-category | F4: Amount (₹) | G4: Paid From | H4: CC Name | I4: Account | J4: Notes | L4: 📊 July Summary | M4: Amount (₹)
A5: =IF(F5<>"",ROW()-4,"") | L5: Total Expenses | M5: =F256
A6: =IF(F6<>"",ROW()-4,"") | L6: Income This Month | M6: =Income!E7
A7: =IF(F7<>"",ROW()-4,"") | L7: Net This Month | M7: =M6-M5
A8: =IF(F8<>"",ROW()-4,"") | L8: Savings 1 (this month) | M8: =IF(Setup!A13<>"",SUMIFS(F5:F255,D5:D255,"Added to Savings",I5:I255,Setup!A13)-SUMIFS(F5:F255,G5:G255,Setup!A13),"")
A9: =IF(F9<>"",ROW()-4,"") | L9: Savings 1 (balance) | M9: =IF(Setup!A13<>"",Setup!B13+(SUMIFS('April'!F5:F64,'April'!D5:D64,"Added to Savings",'April'!I5:I64,Setup!A13)+SUMIFS('May'!F5:F64,'May'!D5:D64,"Added to Savings",'May'!I5:I64,Setup!A13)+SUMIFS('June'!F5:F64,'June'!D5:D64,"Added to Savings",'June'!I5:I64,Setup!A13)+SUMIFS('July'!F5:F64,'July'!D5:D64,"Added to Savings",'July'!I5:I64,Setup!A13))-(SUMIFS('April'!F5:F64,'April'!G5:G64,Setup!A13)+SUMIFS('May'!F5:F64,'May'!G5:G64,Setup!A13)+SUMIFS('June'!F5:F64,'June'!G5:G64,Setup!A13)+SUMIFS('July'!F5:F64,'July'!G5:G64,Setup!A13)),"")
A10: =IF(F10<>"",ROW()-4,"") | L10: Savings 2 (this month) | M10: =IF(Setup!A14<>"",SUMIFS(F5:F255,D5:D255,"Added to Savings",I5:I255,Setup!A14)-SUMIFS(F5:F255,G5:G255,Setup!A14),"")
A11: =IF(F11<>"",ROW()-4,"") | L11: Savings 2 (balance) | M11: =IF(Setup!A14<>"",Setup!B14+(SUMIFS('April'!F5:F64,'April'!D5:D64,"Added to Savings",'April'!I5:I64,Setup!A14)+SUMIFS('May'!F5:F64,'May'!D5:D64,"Added to Savings",'May'!I5:I64,Setup!A14)+SUMIFS('June'!F5:F64,'June'!D5:D64,"Added to Savings",'June'!I5:I64,Setup!A14)+SUMIFS('July'!F5:F64,'July'!D5:D64,"Added to Savings",'July'!I5:I64,Setup!A14))-(SUMIFS('April'!F5:F64,'April'!G5:G64,Setup!A14)+SUMIFS('May'!F5:F64,'May'!G5:G64,Setup!A14)+SUMIFS('June'!F5:F64,'June'!G5:G64,Setup!A14)+SUMIFS('July'!F5:F64,'July'!G5:G64,Setup!A14)),"")
A12: =IF(F12<>"",ROW()-4,"") | L12: Savings 3 (this month) | M12: =IF(Setup!A15<>"",SUMIFS(F5:F255,D5:D255,"Added to Savings",I5:I255,Setup!A15)-SUMIFS(F5:F255,G5:G255,Setup!A15),"")
A13: =IF(F13<>"",ROW()-4,"") | L13: Savings 3 (balance) | M13: =IF(Setup!A15<>"",Setup!B15+(SUMIFS('April'!F5:F64,'April'!D5:D64,"Added to Savings",'April'!I5:I64,Setup!A15)+SUMIFS('May'!F5:F64,'May'!D5:D64,"Added to Savings",'May'!I5:I64,Setup!A15)+SUMIFS('June'!F5:F64,'June'!D5:D64,"Added to Savings",'June'!I5:I64,Setup!A15)+SUMIFS('July'!F5:F64,'July'!D5:D64,"Added to Savings",'July'!I5:I64,Setup!A15))-(SUMIFS('April'!F5:F64,'April'!G5:G64,Setup!A15)+SUMIFS('May'!F5:F64,'May'!G5:G64,Setup!A15)+SUMIFS('June'!F5:F64,'June'!G5:G64,Setup!A15)+SUMIFS('July'!F5:F64,'July'!G5:G64,Setup!A15)),"")
A14: =IF(F14<>"",ROW()-4,"") | L14: Savings 4 (this month) | M14: =IF(Setup!A16<>"",SUMIFS(F5:F255,D5:D255,"Added to Savings",I5:I255,Setup!A16)-SUMIFS(F5:F255,G5:G255,Setup!A16),"")
A15: =IF(F15<>"",ROW()-4,"") | L15: Savings 4 (balance) | M15: =IF(Setup!A16<>"",Setup!B16+(SUMIFS('April'!F5:F64,'April'!D5:D64,"Added to Savings",'April'!I5:I64,Setup!A16)+SUMIFS('May'!F5:F64,'May'!D5:D64,"Added to Savings",'May'!I5:I64,Setup!A16)+SUMIFS('June'!F5:F64,'June'!D5:D64,"Added to Savings",'June'!I5:I64,Setup!A16)+SUMIFS('July'!F5:F64,'July'!D5:D64,"Added to Savings",'July'!I5:I64,Setup!A16))-(SUMIFS('April'!F5:F64,'April'!G5:G64,Setup!A16)+SUMIFS('May'!F5:F64,'May'!G5:G64,Setup!A16)+SUMIFS('June'!F5:F64,'June'!G5:G64,Setup!A16)+SUMIFS('July'!F5:F64,'July'!G5:G64,Setup!A16)),"")
A16: =IF(F16<>"",ROW()-4,"") | L16: Savings 5 (this month) | M16: =IF(Setup!A17<>"",SUMIFS(F5:F255,D5:D255,"Added to Savings",I5:I255,Setup!A17)-SUMIFS(F5:F255,G5:G255,Setup!A17),"")
A17: =IF(F17<>"",ROW()-4,"") | L17: Savings 5 (balance) | M17: =IF(Setup!A17<>"",Setup!B17+(SUMIFS('April'!F5:F64,'April'!D5:D64,"Added to Savings",'April'!I5:I64,Setup!A17)+SUMIFS('May'!F5:F64,'May'!D5:D64,"Added to Savings",'May'!I5:I64,Setup!A17)+SUMIFS('June'!F5:F64,'June'!D5:D64,"Added to Savings",'June'!I5:I64,Setup!A17)+SUMIFS('July'!F5:F64,'July'!D5:D64,"Added to Savings",'July'!I5:I64,Setup!A17))-(SUMIFS('April'!F5:F64,'April'!G5:G64,Setup!A17)+SUMIFS('May'!F5:F64,'May'!G5:G64,Setup!A17)+SUMIFS('June'!F5:F64,'June'!G5:G64,Setup!A17)+SUMIFS('July'!F5:F64,'July'!G5:G64,Setup!A17)),"")
A18: =IF(F18<>"",ROW()-4,"") | L18: Fixed Bills Paid | M18: =SUMIF(D5:D255,"Fixed Bills",F5:F255)
A19: =IF(F19<>"",ROW()-4,"") | L19: Food & Dining | M19: =SUMIF(D5:D255,"Food & Dining",F5:F255)
A20: =IF(F20<>"",ROW()-4,"") | L20: Transport | M20: =SUMIF(D5:D255,"Transport & Fuel",F5:F255)
A21: =IF(F21<>"",ROW()-4,"") | L21: Groceries | M21: =SUMIF(D5:D255,"Groceries",F5:F255)
A22: =IF(F22<>"",ROW()-4,"") | L22: Shopping | M22: =SUMIF(D5:D255,"Shopping & Clothing",F5:F255)
A23: =IF(F23<>"",ROW()-4,"") | L23: Entertainment | M23: =SUMIF(D5:D255,"Entertainment & OTT",F5:F255)
A24: =IF(F24<>"",ROW()-4,"") | L24: Investment | M24: =SUMIF(D5:D255,"Investment",F5:F255)
A25: =IF(F25<>"",ROW()-4,"") | L25: Added to Savings | M25: =SUMIF(D5:D255,"Added to Savings",F5:F255)
A26: =IF(F26<>"",ROW()-4,"") | L26: CC Payments | M26: =SUMIF(D5:D255,"Credit Card Payment",F5:F255)
A27: =IF(F27<>"",ROW()-4,"") | L27: Miscellaneous | M27: =SUMIF(D5:D255,"Miscellaneous",F5:F255)
A28: =IF(F28<>"",ROW()-4,"")
A29: =IF(F29<>"",ROW()-4,"")
A30: =IF(F30<>"",ROW()-4,"")
A31: =IF(F31<>"",ROW()-4,"")
A32: =IF(F32<>"",ROW()-4,"")
A33: =IF(F33<>"",ROW()-4,"")
A34: =IF(F34<>"",ROW()-4,"")
A35: =IF(F35<>"",ROW()-4,"")
A36: =IF(F36<>"",ROW()-4,"")
A37: =IF(F37<>"",ROW()-4,"")
A38: =IF(F38<>"",ROW()-4,"")
A39: =IF(F39<>"",ROW()-4,"")
... A255: =IF(F255<>"",ROW()-4,"")
A256: TOTAL EXPENSES THIS MONTH | F256: =SUM(F5:F255)

Sheet August
A1: 📝 AUGUST — EXPENSE LOG
A2: ℹ️ Date is DateTime. Category dropdown → Sub-category changes automatically. 'Added to Savings' → pick your saving account in Sub-category. CC spend → pick card in 'CC Name'. CC payment → increases card limit.
A4: # | B4: Date & Time | C4: Description | D4: Category | E4: Sub-category | F4: Amount (₹) | G4: Paid From | H4: CC Name | I4: Account | J4: Notes | L4: 📊 August Summary | M4: Amount (₹)
A5: =IF(F5<>"",ROW()-4,"") | L5: Total Expenses | M5: =F256
A6: =IF(F6<>"",ROW()-4,"") | L6: Income This Month | M6: =Income!E8
A7: =IF(F7<>"",ROW()-4,"") | L7: Net This Month | M7: =M6-M5
A8: =IF(F8<>"",ROW()-4,"") | L8: Savings 1 (this month) | M8: =IF(Setup!A13<>"",SUMIFS(F5:F255,D5:D255,"Added to Savings",I5:I255,Setup!A13)-SUMIFS(F5:F255,G5:G255,Setup!A13),"")
A9: =IF(F9<>"",ROW()-4,"") | L9: Savings 1 (balance) | M9: =IF(Setup!A13<>"",Setup!B13+(SUMIFS('April'!F5:F64,'April'!D5:D64,"Added to Savings",'April'!I5:I64,Setup!A13)+SUMIFS('May'!F5:F64,'May'!D5:D64,"Added to Savings",'May'!I5:I64,Setup!A13)+SUMIFS('June'!F5:F64,'June'!D5:D64,"Added to Savings",'June'!I5:I64,Setup!A13)+SUMIFS('July'!F5:F64,'July'!D5:D64,"Added to Savings",'July'!I5:I64,Setup!A13)+SUMIFS('August'!F5:F64,'August'!D5:D64,"Added to Savings",'August'!I5:I64,Setup!A13))-(SUMIFS('April'!F5:F64,'April'!G5:G64,Setup!A13)+SUMIFS('May'!F5:F64,'May'!G5:G64,Setup!A13)+SUMIFS('June'!F5:F64,'June'!G5:G64,Setup!A13)+SUMIFS('July'!F5:F64,'July'!G5:G64,Setup!A13)+SUMIFS('August'!F5:F64,'August'!G5:G64,Setup!A13)),"")
A10: =IF(F10<>"",ROW()-4,"") | L10: Savings 2 (this month) | M10: =IF(Setup!A14<>"",SUMIFS(F5:F255,D5:D255,"Added to Savings",I5:I255,Setup!A14)-SUMIFS(F5:F255,G5:G255,Setup!A14),"")
A11: =IF(F11<>"",ROW()-4,"") | L11: Savings 2 (balance) | M11: =IF(Setup!A14<>"",Setup!B14+(SUMIFS('April'!F5:F64,'April'!D5:D64,"Added to Savings",'April'!I5:I64,Setup!A14)+SUMIFS('May'!F5:F64,'May'!D5:D64,"Added to Savings",'May'!I5:I64,Setup!A14)+SUMIFS('June'!F5:F64,'June'!D5:D64,"Added to Savings",'June'!I5:I64,Setup!A14)+SUMIFS('July'!F5:F64,'July'!D5:D64,"Added to Savings",'July'!I5:I64,Setup!A14)+SUMIFS('August'!F5:F64,'August'!D5:D64,"Added to Savings",'August'!I5:I64,Setup!A14))-(SUMIFS('April'!F5:F64,'April'!G5:G64,Setup!A14)+SUMIFS('May'!F5:F64,'May'!G5:G64,Setup!A14)+SUMIFS('June'!F5:F64,'June'!G5:G64,Setup!A14)+SUMIFS('July'!F5:F64,'July'!G5:G64,Setup!A14)+SUMIFS('August'!F5:F64,'August'!G5:G64,Setup!A14)),"")
A12: =IF(F12<>"",ROW()-4,"") | L12: Savings 3 (this month) | M12: =IF(Setup!A15<>"",SUMIFS(F5:F255,D5:D255,"Added to Savings",I5:I255,Setup!A15)-SUMIFS(F5:F255,G5:G255,Setup!A15),"")
A13: =IF(F13<>"",ROW()-4,"") | L13: Savings 3 (balance) | M13: =IF(Setup!A15<>"",Setup!B15+(SUMIFS('April'!F5:F64,'April'!D5:D64,"Added to Savings",'April'!I5:I64,Setup!A15)+SUMIFS('May'!F5:F64,'May'!D5:D64,"Added to Savings",'May'!I5:I64,Setup!A15)+SUMIFS('June'!F5:F64,'June'!D5:D64,"Added to Savings",'June'!I5:I64,Setup!A15)+SUMIFS('July'!F5:F64,'July'!D5:D64,"Added to Savings",'July'!I5:I64,Setup!A15)+SUMIFS('August'!F5:F64,'August'!D5:D64,"Added to Savings",'August'!I5:I64,Setup!A15))-(SUMIFS('April'!F5:F64,'April'!G5:G64,Setup!A15)+SUMIFS('May'!F5:F64,'May'!G5:G64,Setup!A15)+SUMIFS('June'!F5:F64,'June'!G5:G64,Setup!A15)+SUMIFS('July'!F5:F64,'July'!G5:G64,Setup!A15)+SUMIFS('August'!F5:F64,'August'!G5:G64,Setup!A15)),"")
A14: =IF(F14<>"",ROW()-4,"") | L14: Savings 4 (this month) | M14: =IF(Setup!A16<>"",SUMIFS(F5:F255,D5:D255,"Added to Savings",I5:I255,Setup!A16)-SUMIFS(F5:F255,G5:G255,Setup!A16),"")
A15: =IF(F15<>"",ROW()-4,"") | L15: Savings 4 (balance) | M15: =IF(Setup!A16<>"",Setup!B16+(SUMIFS('April'!F5:F64,'April'!D5:D64,"Added to Savings",'April'!I5:I64,Setup!A16)+SUMIFS('May'!F5:F64,'May'!D5:D64,"Added to Savings",'May'!I5:I64,Setup!A16)+SUMIFS('June'!F5:F64,'June'!D5:D64,"Added to Savings",'June'!I5:I64,Setup!A16)+SUMIFS('July'!F5:F64,'July'!D5:D64,"Added to Savings",'July'!I5:I64,Setup!A16)+SUMIFS('August'!F5:F64,'August'!D5:D64,"Added to Savings",'August'!I5:I64,Setup!A16))-(SUMIFS('April'!F5:F64,'April'!G5:G64,Setup!A16)+SUMIFS('May'!F5:F64,'May'!G5:G64,Setup!A16)+SUMIFS('June'!F5:F64,'June'!G5:G64,Setup!A16)+SUMIFS('July'!F5:F64,'July'!G5:G64,Setup!A16)+SUMIFS('August'!F5:F64,'August'!G5:G64,Setup!A16)),"")
A16: =IF(F16<>"",ROW()-4,"") | L16: Savings 5 (this month) | M16: =IF(Setup!A17<>"",SUMIFS(F5:F255,D5:D255,"Added to Savings",I5:I255,Setup!A17)-SUMIFS(F5:F255,G5:G255,Setup!A17),"")
A17: =IF(F17<>"",ROW()-4,"") | L17: Savings 5 (balance) | M17: =IF(Setup!A17<>"",Setup!B17+(SUMIFS('April'!F5:F64,'April'!D5:D64,"Added to Savings",'April'!I5:I64,Setup!A17)+SUMIFS('May'!F5:F64,'May'!D5:D64,"Added to Savings",'May'!I5:I64,Setup!A17)+SUMIFS('June'!F5:F64,'June'!D5:D64,"Added to Savings",'June'!I5:I64,Setup!A17)+SUMIFS('July'!F5:F64,'July'!D5:D64,"Added to Savings",'July'!I5:I64,Setup!A17)+SUMIFS('August'!F5:F64,'August'!D5:D64,"Added to Savings",'August'!I5:I64,Setup!A17))-(SUMIFS('April'!F5:F64,'April'!G5:G64,Setup!A17)+SUMIFS('May'!F5:F64,'May'!G5:G64,Setup!A17)+SUMIFS('June'!F5:F64,'June'!G5:G64,Setup!A17)+SUMIFS('July'!F5:F64,'July'!G5:G64,Setup!A17)+SUMIFS('August'!F5:F64,'August'!G5:G64,Setup!A17)),"")
A18: =IF(F18<>"",ROW()-4,"") | L18: Fixed Bills Paid | M18: =SUMIF(D5:D255,"Fixed Bills",F5:F255)
A19: =IF(F19<>"",ROW()-4,"") | L19: Food & Dining | M19: =SUMIF(D5:D255,"Food & Dining",F5:F255)
A20: =IF(F20<>"",ROW()-4,"") | L20: Transport | M20: =SUMIF(D5:D255,"Transport & Fuel",F5:F255)
A21: =IF(F21<>"",ROW()-4,"") | L21: Groceries | M21: =SUMIF(D5:D255,"Groceries",F5:F255)
A22: =IF(F22<>"",ROW()-4,"") | L22: Shopping | M22: =SUMIF(D5:D255,"Shopping & Clothing",F5:F255)
A23: =IF(F23<>"",ROW()-4,"") | L23: Entertainment | M23: =SUMIF(D5:D255,"Entertainment & OTT",F5:F255)
A24: =IF(F24<>"",ROW()-4,"") | L24: Investment | M24: =SUMIF(D5:D255,"Investment",F5:F255)
A25: =IF(F25<>"",ROW()-4,"") | L25: Added to Savings | M25: =SUMIF(D5:D255,"Added to Savings",F5:F255)
A26: =IF(F26<>"",ROW()-4,"") | L26: CC Payments | M26: =SUMIF(D5:D255,"Credit Card Payment",F5:F255)
A27: =IF(F27<>"",ROW()-4,"") | L27: Miscellaneous | M27: =SUMIF(D5:D255,"Miscellaneous",F5:F255)
A28: =IF(F28<>"",ROW()-4,"")
A29: =IF(F29<>"",ROW()-4,"")
A30: =IF(F30<>"",ROW()-4,"")
A31: =IF(F31<>"",ROW()-4,"")
A32: =IF(F32<>"",ROW()-4,"")
A33: =IF(F33<>"",ROW()-4,"")
A34: =IF(F34<>"",ROW()-4,"")
A35: =IF(F35<>"",ROW()-4,"")
A36: =IF(F36<>"",ROW()-4,"")
A37: =IF(F37<>"",ROW()-4,"")
A38: =IF(F38<>"",ROW()-4,"")
A39: =IF(F39<>"",ROW()-4,"")
... A255: =IF(F255<>"",ROW()-4,"")
A256: TOTAL EXPENSES THIS MONTH | F256: =SUM(F5:F255)

Sheet September
A1: 📝 SEPTEMBER — EXPENSE LOG
A2: ℹ️ Date is DateTime. Category dropdown → Sub-category changes automatically. 'Added to Savings' → pick your saving account in Sub-category. CC spend → pick card in 'CC Name'. CC payment → increases card limit.
A4: # | B4: Date & Time | C4: Description | D4: Category | E4: Sub-category | F4: Amount (₹) | G4: Paid From | H4: CC Name | I4: Account | J4: Notes | L4: 📊 September Summary | M4: Amount (₹)
A5: =IF(F5<>"",ROW()-4,"") | L5: Total Expenses | M5: =F256
A6: =IF(F6<>"",ROW()-4,"") | L6: Income This Month | M6: =Income!E9
A7: =IF(F7<>"",ROW()-4,"") | L7: Net This Month | M7: =M6-M5
A8: =IF(F8<>"",ROW()-4,"") | L8: Savings 1 (this month) | M8: =IF(Setup!A13<>"",SUMIFS(F5:F255,D5:D255,"Added to Savings",I5:I255,Setup!A13)-SUMIFS(F5:F255,G5:G255,Setup!A13),"")
A9: =IF(F9<>"",ROW()-4,"") | L9: Savings 1 (balance) | M9: =IF(Setup!A13<>"",Setup!B13+(SUMIFS('April'!F5:F64,'April'!D5:D64,"Added to Savings",'April'!I5:I64,Setup!A13)+SUMIFS('May'!F5:F64,'May'!D5:D64,"Added to Savings",'May'!I5:I64,Setup!A13)+SUMIFS('June'!F5:F64,'June'!D5:D64,"Added to Savings",'June'!I5:I64,Setup!A13)+SUMIFS('July'!F5:F64,'July'!D5:D64,"Added to Savings",'July'!I5:I64,Setup!A13)+SUMIFS('August'!F5:F64,'August'!D5:D64,"Added to Savings",'August'!I5:I64,Setup!A13)+SUMIFS('September'!F5:F64,'September'!D5:D64,"Added to Savings",'September'!I5:I64,Setup!A13))-(SUMIFS('April'!F5:F64,'April'!G5:G64,Setup!A13)+SUMIFS('May'!F5:F64,'May'!G5:G64,Setup!A13)+SUMIFS('June'!F5:F64,'June'!G5:G64,Setup!A13)+SUMIFS('July'!F5:F64,'July'!G5:G64,Setup!A13)+SUMIFS('August'!F5:F64,'August'!G5:G64,Setup!A13)+SUMIFS('September'!F5:F64,'September'!G5:G64,Setup!A13)),"")
A10: =IF(F10<>"",ROW()-4,"") | L10: Savings 2 (this month) | M10: =IF(Setup!A14<>"",SUMIFS(F5:F255,D5:D255,"Added to Savings",I5:I255,Setup!A14)-SUMIFS(F5:F255,G5:G255,Setup!A14),"")
A11: =IF(F11<>"",ROW()-4,"") | L11: Savings 2 (balance) | M11: =IF(Setup!A14<>"",Setup!B14+(SUMIFS('April'!F5:F64,'April'!D5:D64,"Added to Savings",'April'!I5:I64,Setup!A14)+SUMIFS('May'!F5:F64,'May'!D5:D64,"Added to Savings",'May'!I5:I64,Setup!A14)+SUMIFS('June'!F5:F64,'June'!D5:D64,"Added to Savings",'June'!I5:I64,Setup!A14)+SUMIFS('July'!F5:F64,'July'!D5:D64,"Added to Savings",'July'!I5:I64,Setup!A14)+SUMIFS('August'!F5:F64,'August'!D5:D64,"Added to Savings",'August'!I5:I64,Setup!A14)+SUMIFS('September'!F5:F64,'September'!D5:D64,"Added to Savings",'September'!I5:I64,Setup!A14))-(SUMIFS('April'!F5:F64,'April'!G5:G64,Setup!A14)+SUMIFS('May'!F5:F64,'May'!G5:G64,Setup!A14)+SUMIFS('June'!F5:F64,'June'!G5:G64,Setup!A14)+SUMIFS('July'!F5:F64,'July'!G5:G64,Setup!A14)+SUMIFS('August'!F5:F64,'August'!G5:G64,Setup!A14)+SUMIFS('September'!F5:F64,'September'!G5:G64,Setup!A14)),"")
A12: =IF(F12<>"",ROW()-4,"") | L12: Savings 3 (this month) | M12: =IF(Setup!A15<>"",SUMIFS(F5:F255,D5:D255,"Added to Savings",I5:I255,Setup!A15)-SUMIFS(F5:F255,G5:G255,Setup!A15),"")
A13: =IF(F13<>"",ROW()-4,"") | L13: Savings 3 (balance) | M13: =IF(Setup!A15<>"",Setup!B15+(SUMIFS('April'!F5:F64,'April'!D5:D64,"Added to Savings",'April'!I5:I64,Setup!A15)+SUMIFS('May'!F5:F64,'May'!D5:D64,"Added to Savings",'May'!I5:I64,Setup!A15)+SUMIFS('June'!F5:F64,'June'!D5:D64,"Added to Savings",'June'!I5:I64,Setup!A15)+SUMIFS('July'!F5:F64,'July'!D5:D64,"Added to Savings",'July'!I5:I64,Setup!A15)+SUMIFS('August'!F5:F64,'August'!D5:D64,"Added to Savings",'August'!I5:I64,Setup!A15)+SUMIFS('September'!F5:F64,'September'!D5:D64,"Added to Savings",'September'!I5:I64,Setup!A15))-(SUMIFS('April'!F5:F64,'April'!G5:G64,Setup!A15)+SUMIFS('May'!F5:F64,'May'!G5:G64,Setup!A15)+SUMIFS('June'!F5:F64,'June'!G5:G64,Setup!A15)+SUMIFS('July'!F5:F64,'July'!G5:G64,Setup!A15)+SUMIFS('August'!F5:F64,'August'!G5:G64,Setup!A15)+SUMIFS('September'!F5:F64,'September'!G5:G64,Setup!A15)),"")
A14: =IF(F14<>"",ROW()-4,"") | L14: Savings 4 (this month) | M14: =IF(Setup!A16<>"",SUMIFS(F5:F255,D5:D255,"Added to Savings",I5:I255,Setup!A16)-SUMIFS(F5:F255,G5:G255,Setup!A16),"")
A15: =IF(F15<>"",ROW()-4,"") | L15: Savings 4 (balance) | M15: =IF(Setup!A16<>"",Setup!B16+(SUMIFS('April'!F5:F64,'April'!D5:D64,"Added to Savings",'April'!I5:I64,Setup!A16)+SUMIFS('May'!F5:F64,'May'!D5:D64,"Added to Savings",'May'!I5:I64,Setup!A16)+SUMIFS('June'!F5:F64,'June'!D5:D64,"Added to Savings",'June'!I5:I64,Setup!A16)+SUMIFS('July'!F5:F64,'July'!D5:D64,"Added to Savings",'July'!I5:I64,Setup!A16)+SUMIFS('August'!F5:F64,'August'!D5:D64,"Added to Savings",'August'!I5:I64,Setup!A16)+SUMIFS('September'!F5:F64,'September'!D5:D64,"Added to Savings",'September'!I5:I64,Setup!A16))-(SUMIFS('April'!F5:F64,'April'!G5:G64,Setup!A16)+SUMIFS('May'!F5:F64,'May'!G5:G64,Setup!A16)+SUMIFS('June'!F5:F64,'June'!G5:G64,Setup!A16)+SUMIFS('July'!F5:F64,'July'!G5:G64,Setup!A16)+SUMIFS('August'!F5:F64,'August'!G5:G64,Setup!A16)+SUMIFS('September'!F5:F64,'September'!G5:G64,Setup!A16)),"")
A16: =IF(F16<>"",ROW()-4,"") | L16: Savings 5 (this month) | M16: =IF(Setup!A17<>"",SUMIFS(F5:F255,D5:D255,"Added to Savings",I5:I255,Setup!A17)-SUMIFS(F5:F255,G5:G255,Setup!A17),"")
A17: =IF(F17<>"",ROW()-4,"") | L17: Savings 5 (balance) | M17: =IF(Setup!A17<>"",Setup!B17+(SUMIFS('April'!F5:F64,'April'!D5:D64,"Added to Savings",'April'!I5:I64,Setup!A17)+SUMIFS('May'!F5:F64,'May'!D5:D64,"Added to Savings",'May'!I5:I64,Setup!A17)+SUMIFS('June'!F5:F64,'June'!D5:D64,"Added to Savings",'June'!I5:I64,Setup!A17)+SUMIFS('July'!F5:F64,'July'!D5:D64,"Added to Savings",'July'!I5:I64,Setup!A17)+SUMIFS('August'!F5:F64,'August'!D5:D64,"Added to Savings",'August'!I5:I64,Setup!A17)+SUMIFS('September'!F5:F64,'September'!D5:D64,"Added to Savings",'September'!I5:I64,Setup!A17))-(SUMIFS('April'!F5:F64,'April'!G5:G64,Setup!A17)+SUMIFS('May'!F5:F64,'May'!G5:G64,Setup!A17)+SUMIFS('June'!F5:F64,'June'!G5:G64,Setup!A17)+SUMIFS('July'!F5:F64,'July'!G5:G64,Setup!A17)+SUMIFS('August'!F5:F64,'August'!G5:G64,Setup!A17)+SUMIFS('September'!F5:F64,'September'!G5:G64,Setup!A17)),"")
A18: =IF(F18<>"",ROW()-4,"") | L18: Fixed Bills Paid | M18: =SUMIF(D5:D255,"Fixed Bills",F5:F255)
A19: =IF(F19<>"",ROW()-4,"") | L19: Food & Dining | M19: =SUMIF(D5:D255,"Food & Dining",F5:F255)
A20: =IF(F20<>"",ROW()-4,"") | L20: Transport | M20: =SUMIF(D5:D255,"Transport & Fuel",F5:F255)
A21: =IF(F21<>"",ROW()-4,"") | L21: Groceries | M21: =SUMIF(D5:D255,"Groceries",F5:F255)
A22: =IF(F22<>"",ROW()-4,"") | L22: Shopping | M22: =SUMIF(D5:D255,"Shopping & Clothing",F5:F255)
A23: =IF(F23<>"",ROW()-4,"") | L23: Entertainment | M23: =SUMIF(D5:D255,"Entertainment & OTT",F5:F255)
A24: =IF(F24<>"",ROW()-4,"") | L24: Investment | M24: =SUMIF(D5:D255,"Investment",F5:F255)
A25: =IF(F25<>"",ROW()-4,"") | L25: Added to Savings | M25: =SUMIF(D5:D255,"Added to Savings",F5:F255)
A26: =IF(F26<>"",ROW()-4,"") | L26: CC Payments | M26: =SUMIF(D5:D255,"Credit Card Payment",F5:F255)
A27: =IF(F27<>"",ROW()-4,"") | L27: Miscellaneous | M27: =SUMIF(D5:D255,"Miscellaneous",F5:F255)
A28: =IF(F28<>"",ROW()-4,"")
A29: =IF(F29<>"",ROW()-4,"")
A30: =IF(F30<>"",ROW()-4,"")
A31: =IF(F31<>"",ROW()-4,"")
A32: =IF(F32<>"",ROW()-4,"")
A33: =IF(F33<>"",ROW()-4,"")
A34: =IF(F34<>"",ROW()-4,"")
A35: =IF(F35<>"",ROW()-4,"")
A36: =IF(F36<>"",ROW()-4,"")
A37: =IF(F37<>"",ROW()-4,"")
A38: =IF(F38<>"",ROW()-4,"")
A39: =IF(F39<>"",ROW()-4,"")
... A255: =IF(F255<>"",ROW()-4,"")
A256: TOTAL EXPENSES THIS MONTH | F256: =SUM(F5:F255)

Sheet October
A1: 📝 OCTOBER — EXPENSE LOG
A2: ℹ️ Date is DateTime. Category dropdown → Sub-category changes automatically. 'Added to Savings' → pick your saving account in Sub-category. CC spend → pick card in 'CC Name'. CC payment → increases card limit.
A4: # | B4: Date & Time | C4: Description | D4: Category | E4: Sub-category | F4: Amount (₹) | G4: Paid From | H4: CC Name | I4: Account | J4: Notes | L4: 📊 October Summary | M4: Amount (₹)
A5: =IF(F5<>"",ROW()-4,"") | L5: Total Expenses | M5: =F256
A6: =IF(F6<>"",ROW()-4,"") | L6: Income This Month | M6: =Income!E10
A7: =IF(F7<>"",ROW()-4,"") | L7: Net This Month | M7: =M6-M5
A8: =IF(F8<>"",ROW()-4,"") | L8: Savings 1 (this month) | M8: =IF(Setup!A13<>"",SUMIFS(F5:F255,D5:D255,"Added to Savings",I5:I255,Setup!A13)-SUMIFS(F5:F255,G5:G255,Setup!A13),"")
A9: =IF(F9<>"",ROW()-4,"") | L9: Savings 1 (balance) | M9: =IF(Setup!A13<>"",Setup!B13+(SUMIFS('April'!F5:F64,'April'!D5:D64,"Added to Savings",'April'!I5:I64,Setup!A13)+SUMIFS('May'!F5:F64,'May'!D5:D64,"Added to Savings",'May'!I5:I64,Setup!A13)+SUMIFS('June'!F5:F64,'June'!D5:D64,"Added to Savings",'June'!I5:I64,Setup!A13)+SUMIFS('July'!F5:F64,'July'!D5:D64,"Added to Savings",'July'!I5:I64,Setup!A13)+SUMIFS('August'!F5:F64,'August'!D5:D64,"Added to Savings",'August'!I5:I64,Setup!A13)+SUMIFS('September'!F5:F64,'September'!D5:D64,"Added to Savings",'September'!I5:I64,Setup!A13)+SUMIFS('October'!F5:F64,'October'!D5:D64,"Added to Savings",'October'!I5:I64,Setup!A13))-(SUMIFS('April'!F5:F64,'April'!G5:G64,Setup!A13)+SUMIFS('May'!F5:F64,'May'!G5:G64,Setup!A13)+SUMIFS('June'!F5:F64,'June'!G5:G64,Setup!A13)+SUMIFS('July'!F5:F64,'July'!G5:G64,Setup!A13)+SUMIFS('August'!F5:F64,'August'!G5:G64,Setup!A13)+SUMIFS('September'!F5:F64,'September'!G5:G64,Setup!A13)+SUMIFS('October'!F5:F64,'October'!G5:G64,Setup!A13)),"")
A10: =IF(F10<>"",ROW()-4,"") | L10: Savings 2 (this month) | M10: =IF(Setup!A14<>"",SUMIFS(F5:F255,D5:D255,"Added to Savings",I5:I255,Setup!A14)-SUMIFS(F5:F255,G5:G255,Setup!A14),"")
A11: =IF(F11<>"",ROW()-4,"") | L11: Savings 2 (balance) | M11: =IF(Setup!A14<>"",Setup!B14+(SUMIFS('April'!F5:F64,'April'!D5:D64,"Added to Savings",'April'!I5:I64,Setup!A14)+SUMIFS('May'!F5:F64,'May'!D5:D64,"Added to Savings",'May'!I5:I64,Setup!A14)+SUMIFS('June'!F5:F64,'June'!D5:D64,"Added to Savings",'June'!I5:I64,Setup!A14)+SUMIFS('July'!F5:F64,'July'!D5:D64,"Added to Savings",'July'!I5:I64,Setup!A14)+SUMIFS('August'!F5:F64,'August'!D5:D64,"Added to Savings",'August'!I5:I64,Setup!A14)+SUMIFS('September'!F5:F64,'September'!D5:D64,"Added to Savings",'September'!I5:I64,Setup!A14)+SUMIFS('October'!F5:F64,'October'!D5:D64,"Added to Savings",'October'!I5:I64,Setup!A14))-(SUMIFS('April'!F5:F64,'April'!G5:G64,Setup!A14)+SUMIFS('May'!F5:F64,'May'!G5:G64,Setup!A14)+SUMIFS('June'!F5:F64,'June'!G5:G64,Setup!A14)+SUMIFS('July'!F5:F64,'July'!G5:G64,Setup!A14)+SUMIFS('August'!F5:F64,'August'!G5:G64,Setup!A14)+SUMIFS('September'!F5:F64,'September'!G5:G64,Setup!A14)+SUMIFS('October'!F5:F64,'October'!G5:G64,Setup!A14)),"")
A12: =IF(F12<>"",ROW()-4,"") | L12: Savings 3 (this month) | M12: =IF(Setup!A15<>"",SUMIFS(F5:F255,D5:D255,"Added to Savings",I5:I255,Setup!A15)-SUMIFS(F5:F255,G5:G255,Setup!A15),"")
A13: =IF(F13<>"",ROW()-4,"") | L13: Savings 3 (balance) | M13: =IF(Setup!A15<>"",Setup!B15+(SUMIFS('April'!F5:F64,'April'!D5:D64,"Added to Savings",'April'!I5:I64,Setup!A15)+SUMIFS('May'!F5:F64,'May'!D5:D64,"Added to Savings",'May'!I5:I64,Setup!A15)+SUMIFS('June'!F5:F64,'June'!D5:D64,"Added to Savings",'June'!I5:I64,Setup!A15)+SUMIFS('July'!F5:F64,'July'!D5:D64,"Added to Savings",'July'!I5:I64,Setup!A15)+SUMIFS('August'!F5:F64,'August'!D5:D64,"Added to Savings",'August'!I5:I64,Setup!A15)+SUMIFS('September'!F5:F64,'September'!D5:D64,"Added to Savings",'September'!I5:I64,Setup!A15)+SUMIFS('October'!F5:F64,'October'!D5:D64,"Added to Savings",'October'!I5:I64,Setup!A15))-(SUMIFS('April'!F5:F64,'April'!G5:G64,Setup!A15)+SUMIFS('May'!F5:F64,'May'!G5:G64,Setup!A15)+SUMIFS('June'!F5:F64,'June'!G5:G64,Setup!A15)+SUMIFS('July'!F5:F64,'July'!G5:G64,Setup!A15)+SUMIFS('August'!F5:F64,'August'!G5:G64,Setup!A15)+SUMIFS('September'!F5:F64,'September'!G5:G64,Setup!A15)+SUMIFS('October'!F5:F64,'October'!G5:G64,Setup!A15)),"")
A14: =IF(F14<>"",ROW()-4,"") | L14: Savings 4 (this month) | M14: =IF(Setup!A16<>"",SUMIFS(F5:F255,D5:D255,"Added to Savings",I5:I255,Setup!A16)-SUMIFS(F5:F255,G5:G255,Setup!A16),"")
A15: =IF(F15<>"",ROW()-4,"") | L15: Savings 4 (balance) | M15: =IF(Setup!A16<>"",Setup!B16+(SUMIFS('April'!F5:F64,'April'!D5:D64,"Added to Savings",'April'!I5:I64,Setup!A16)+SUMIFS('May'!F5:F64,'May'!D5:D64,"Added to Savings",'May'!I5:I64,Setup!A16)+SUMIFS('June'!F5:F64,'June'!D5:D64,"Added to Savings",'June'!I5:I64,Setup!A16)+SUMIFS('July'!F5:F64,'July'!D5:D64,"Added to Savings",'July'!I5:I64,Setup!A16)+SUMIFS('August'!F5:F64,'August'!D5:D64,"Added to Savings",'August'!I5:I64,Setup!A16)+SUMIFS('September'!F5:F64,'September'!D5:D64,"Added to Savings",'September'!I5:I64,Setup!A16)+SUMIFS('October'!F5:F64,'October'!D5:D64,"Added to Savings",'October'!I5:I64,Setup!A16))-(SUMIFS('April'!F5:F64,'April'!G5:G64,Setup!A16)+SUMIFS('May'!F5:F64,'May'!G5:G64,Setup!A16)+SUMIFS('June'!F5:F64,'June'!G5:G64,Setup!A16)+SUMIFS('July'!F5:F64,'July'!G5:G64,Setup!A16)+SUMIFS('August'!F5:F64,'August'!G5:G64,Setup!A16)+SUMIFS('September'!F5:F64,'September'!G5:G64,Setup!A16)+SUMIFS('October'!F5:F64,'October'!G5:G64,Setup!A16)),"")
A16: =IF(F16<>"",ROW()-4,"") | L16: Savings 5 (this month) | M16: =IF(Setup!A17<>"",SUMIFS(F5:F255,D5:D255,"Added to Savings",I5:I255,Setup!A17)-SUMIFS(F5:F255,G5:G255,Setup!A17),"")
A17: =IF(F17<>"",ROW()-4,"") | L17: Savings 5 (balance) | M17: =IF(Setup!A17<>"",Setup!B17+(SUMIFS('April'!F5:F64,'April'!D5:D64,"Added to Savings",'April'!I5:I64,Setup!A17)+SUMIFS('May'!F5:F64,'May'!D5:D64,"Added to Savings",'May'!I5:I64,Setup!A17)+SUMIFS('June'!F5:F64,'June'!D5:D64,"Added to Savings",'June'!I5:I64,Setup!A17)+SUMIFS('July'!F5:F64,'July'!D5:D64,"Added to Savings",'July'!I5:I64,Setup!A17)+SUMIFS('August'!F5:F64,'August'!D5:D64,"Added to Savings",'August'!I5:I64,Setup!A17)+SUMIFS('September'!F5:F64,'September'!D5:D64,"Added to Savings",'September'!I5:I64,Setup!A17)+SUMIFS('October'!F5:F64,'October'!D5:D64,"Added to Savings",'October'!I5:I64,Setup!A17))-(SUMIFS('April'!F5:F64,'April'!G5:G64,Setup!A17)+SUMIFS('May'!F5:F64,'May'!G5:G64,Setup!A17)+SUMIFS('June'!F5:F64,'June'!G5:G64,Setup!A17)+SUMIFS('July'!F5:F64,'July'!G5:G64,Setup!A17)+SUMIFS('August'!F5:F64,'August'!G5:G64,Setup!A17)+SUMIFS('September'!F5:F64,'September'!G5:G64,Setup!A17)+SUMIFS('October'!F5:F64,'October'!G5:G64,Setup!A17)),"")
A18: =IF(F18<>"",ROW()-4,"") | L18: Fixed Bills Paid | M18: =SUMIF(D5:D255,"Fixed Bills",F5:F255)
A19: =IF(F19<>"",ROW()-4,"") | L19: Food & Dining | M19: =SUMIF(D5:D255,"Food & Dining",F5:F255)
A20: =IF(F20<>"",ROW()-4,"") | L20: Transport | M20: =SUMIF(D5:D255,"Transport & Fuel",F5:F255)
A21: =IF(F21<>"",ROW()-4,"") | L21: Groceries | M21: =SUMIF(D5:D255,"Groceries",F5:F255)
A22: =IF(F22<>"",ROW()-4,"") | L22: Shopping | M22: =SUMIF(D5:D255,"Shopping & Clothing",F5:F255)
A23: =IF(F23<>"",ROW()-4,"") | L23: Entertainment | M23: =SUMIF(D5:D255,"Entertainment & OTT",F5:F255)
A24: =IF(F24<>"",ROW()-4,"") | L24: Investment | M24: =SUMIF(D5:D255,"Investment",F5:F255)
A25: =IF(F25<>"",ROW()-4,"") | L25: Added to Savings | M25: =SUMIF(D5:D255,"Added to Savings",F5:F255)
A26: =IF(F26<>"",ROW()-4,"") | L26: CC Payments | M26: =SUMIF(D5:D255,"Credit Card Payment",F5:F255)
A27: =IF(F27<>"",ROW()-4,"") | L27: Miscellaneous | M27: =SUMIF(D5:D255,"Miscellaneous",F5:F255)
A28: =IF(F28<>"",ROW()-4,"")
A29: =IF(F29<>"",ROW()-4,"")
A30: =IF(F30<>"",ROW()-4,"")
A31: =IF(F31<>"",ROW()-4,"")
A32: =IF(F32<>"",ROW()-4,"")
A33: =IF(F33<>"",ROW()-4,"")
A34: =IF(F34<>"",ROW()-4,"")
A35: =IF(F35<>"",ROW()-4,"")
A36: =IF(F36<>"",ROW()-4,"")
A37: =IF(F37<>"",ROW()-4,"")
A38: =IF(F38<>"",ROW()-4,"")
A39: =IF(F39<>"",ROW()-4,"")
... A255: =IF(F255<>"",ROW()-4,"")
A256: TOTAL EXPENSES THIS MONTH | F256: =SUM(F5:F255)

Sheet November
A1: 📝 NOVEMBER — EXPENSE LOG
A2: ℹ️ Date is DateTime. Category dropdown → Sub-category changes automatically. 'Added to Savings' → pick your saving account in Sub-category. CC spend → pick card in 'CC Name'. CC payment → increases card limit.
A4: # | B4: Date & Time | C4: Description | D4: Category | E4: Sub-category | F4: Amount (₹) | G4: Paid From | H4: CC Name | I4: Account | J4: Notes | L4: 📊 November Summary | M4: Amount (₹)
A5: =IF(F5<>"",ROW()-4,"") | L5: Total Expenses | M5: =F256
A6: =IF(F6<>"",ROW()-4,"") | L6: Income This Month | M6: =Income!E11
A7: =IF(F7<>"",ROW()-4,"") | L7: Net This Month | M7: =M6-M5
A8: =IF(F8<>"",ROW()-4,"") | L8: Savings 1 (this month) | M8: =IF(Setup!A13<>"",SUMIFS(F5:F255,D5:D255,"Added to Savings",I5:I255,Setup!A13)-SUMIFS(F5:F255,G5:G255,Setup!A13),"")
A9: =IF(F9<>"",ROW()-4,"") | L9: Savings 1 (balance) | M9: =IF(Setup!A13<>"",Setup!B13+(SUMIFS('April'!F5:F64,'April'!D5:D64,"Added to Savings",'April'!I5:I64,Setup!A13)+SUMIFS('May'!F5:F64,'May'!D5:D64,"Added to Savings",'May'!I5:I64,Setup!A13)+SUMIFS('June'!F5:F64,'June'!D5:D64,"Added to Savings",'June'!I5:I64,Setup!A13)+SUMIFS('July'!F5:F64,'July'!D5:D64,"Added to Savings",'July'!I5:I64,Setup!A13)+SUMIFS('August'!F5:F64,'August'!D5:D64,"Added to Savings",'August'!I5:I64,Setup!A13)+SUMIFS('September'!F5:F64,'September'!D5:D64,"Added to Savings",'September'!I5:I64,Setup!A13)+SUMIFS('October'!F5:F64,'October'!D5:D64,"Added to Savings",'October'!I5:I64,Setup!A13)+SUMIFS('November'!F5:F64,'November'!D5:D64,"Added to Savings",'November'!I5:I64,Setup!A13))-(SUMIFS('April'!F5:F64,'April'!G5:G64,Setup!A13)+SUMIFS('May'!F5:F64,'May'!G5:G64,Setup!A13)+SUMIFS('June'!F5:F64,'June'!G5:G64,Setup!A13)+SUMIFS('July'!F5:F64,'July'!G5:G64,Setup!A13)+SUMIFS('August'!F5:F64,'August'!G5:G64,Setup!A13)+SUMIFS('September'!F5:F64,'September'!G5:G64,Setup!A13)+SUMIFS('October'!F5:F64,'October'!G5:G64,Setup!A13)+SUMIFS('November'!F5:F64,'November'!G5:G64,Setup!A13)),"")
A10: =IF(F10<>"",ROW()-4,"") | L10: Savings 2 (this month) | M10: =IF(Setup!A14<>"",SUMIFS(F5:F255,D5:D255,"Added to Savings",I5:I255,Setup!A14)-SUMIFS(F5:F255,G5:G255,Setup!A14),"")
A11: =IF(F11<>"",ROW()-4,"") | L11: Savings 2 (balance) | M11: =IF(Setup!A14<>"",Setup!B14+(SUMIFS('April'!F5:F64,'April'!D5:D64,"Added to Savings",'April'!I5:I64,Setup!A14)+SUMIFS('May'!F5:F64,'May'!D5:D64,"Added to Savings",'May'!I5:I64,Setup!A14)+SUMIFS('June'!F5:F64,'June'!D5:D64,"Added to Savings",'June'!I5:I64,Setup!A14)+SUMIFS('July'!F5:F64,'July'!D5:D64,"Added to Savings",'July'!I5:I64,Setup!A14)+SUMIFS('August'!F5:F64,'August'!D5:D64,"Added to Savings",'August'!I5:I64,Setup!A14)+SUMIFS('September'!F5:F64,'September'!D5:D64,"Added to Savings",'September'!I5:I64,Setup!A14)+SUMIFS('October'!F5:F64,'October'!D5:D64,"Added to Savings",'October'!I5:I64,Setup!A14)+SUMIFS('November'!F5:F64,'November'!D5:D64,"Added to Savings",'November'!I5:I64,Setup!A14))-(SUMIFS('April'!F5:F64,'April'!G5:G64,Setup!A14)+SUMIFS('May'!F5:F64,'May'!G5:G64,Setup!A14)+SUMIFS('June'!F5:F64,'June'!G5:G64,Setup!A14)+SUMIFS('July'!F5:F64,'July'!G5:G64,Setup!A14)+SUMIFS('August'!F5:F64,'August'!G5:G64,Setup!A14)+SUMIFS('September'!F5:F64,'September'!G5:G64,Setup!A14)+SUMIFS('October'!F5:F64,'October'!G5:G64,Setup!A14)+SUMIFS('November'!F5:F64,'November'!G5:G64,Setup!A14)),"")
A12: =IF(F12<>"",ROW()-4,"") | L12: Savings 3 (this month) | M12: =IF(Setup!A15<>"",SUMIFS(F5:F255,D5:D255,"Added to Savings",I5:I255,Setup!A15)-SUMIFS(F5:F255,G5:G255,Setup!A15),"")
A13: =IF(F13<>"",ROW()-4,"") | L13: Savings 3 (balance) | M13: =IF(Setup!A15<>"",Setup!B15+(SUMIFS('April'!F5:F64,'April'!D5:D64,"Added to Savings",'April'!I5:I64,Setup!A15)+SUMIFS('May'!F5:F64,'May'!D5:D64,"Added to Savings",'May'!I5:I64,Setup!A15)+SUMIFS('June'!F5:F64,'June'!D5:D64,"Added to Savings",'June'!I5:I64,Setup!A15)+SUMIFS('July'!F5:F64,'July'!D5:D64,"Added to Savings",'July'!I5:I64,Setup!A15)+SUMIFS('August'!F5:F64,'August'!D5:D64,"Added to Savings",'August'!I5:I64,Setup!A15)+SUMIFS('September'!F5:F64,'September'!D5:D64,"Added to Savings",'September'!I5:I64,Setup!A15)+SUMIFS('October'!F5:F64,'October'!D5:D64,"Added to Savings",'October'!I5:I64,Setup!A15)+SUMIFS('November'!F5:F64,'November'!D5:D64,"Added to Savings",'November'!I5:I64,Setup!A15))-(SUMIFS('April'!F5:F64,'April'!G5:G64,Setup!A15)+SUMIFS('May'!F5:F64,'May'!G5:G64,Setup!A15)+SUMIFS('June'!F5:F64,'June'!G5:G64,Setup!A15)+SUMIFS('July'!F5:F64,'July'!G5:G64,Setup!A15)+SUMIFS('August'!F5:F64,'August'!G5:G64,Setup!A15)+SUMIFS('September'!F5:F64,'September'!G5:G64,Setup!A15)+SUMIFS('October'!F5:F64,'October'!G5:G64,Setup!A15)+SUMIFS('November'!F5:F64,'November'!G5:G64,Setup!A15)),"")
A14: =IF(F14<>"",ROW()-4,"") | L14: Savings 4 (this month) | M14: =IF(Setup!A16<>"",SUMIFS(F5:F255,D5:D255,"Added to Savings",I5:I255,Setup!A16)-SUMIFS(F5:F255,G5:G255,Setup!A16),"")
A15: =IF(F15<>"",ROW()-4,"") | L15: Savings 4 (balance) | M15: =IF(Setup!A16<>"",Setup!B16+(SUMIFS('April'!F5:F64,'April'!D5:D64,"Added to Savings",'April'!I5:I64,Setup!A16)+SUMIFS('May'!F5:F64,'May'!D5:D64,"Added to Savings",'May'!I5:I64,Setup!A16)+SUMIFS('June'!F5:F64,'June'!D5:D64,"Added to Savings",'June'!I5:I64,Setup!A16)+SUMIFS('July'!F5:F64,'July'!D5:D64,"Added to Savings",'July'!I5:I64,Setup!A16)+SUMIFS('August'!F5:F64,'August'!D5:D64,"Added to Savings",'August'!I5:I64,Setup!A16)+SUMIFS('September'!F5:F64,'September'!D5:D64,"Added to Savings",'September'!I5:I64,Setup!A16)+SUMIFS('October'!F5:F64,'October'!D5:D64,"Added to Savings",'October'!I5:I64,Setup!A16)+SUMIFS('November'!F5:F64,'November'!D5:D64,"Added to Savings",'November'!I5:I64,Setup!A16))-(SUMIFS('April'!F5:F64,'April'!G5:G64,Setup!A16)+SUMIFS('May'!F5:F64,'May'!G5:G64,Setup!A16)+SUMIFS('June'!F5:F64,'June'!G5:G64,Setup!A16)+SUMIFS('July'!F5:F64,'July'!G5:G64,Setup!A16)+SUMIFS('August'!F5:F64,'August'!G5:G64,Setup!A16)+SUMIFS('September'!F5:F64,'September'!G5:G64,Setup!A16)+SUMIFS('October'!F5:F64,'October'!G5:G64,Setup!A16)+SUMIFS('November'!F5:F64,'November'!G5:G64,Setup!A16)),"")
A16: =IF(F16<>"",ROW()-4,"") | L16: Savings 5 (this month) | M16: =IF(Setup!A17<>"",SUMIFS(F5:F255,D5:D255,"Added to Savings",I5:I255,Setup!A17)-SUMIFS(F5:F255,G5:G255,Setup!A17),"")
A17: =IF(F17<>"",ROW()-4,"") | L17: Savings 5 (balance) | M17: =IF(Setup!A17<>"",Setup!B17+(SUMIFS('April'!F5:F64,'April'!D5:D64,"Added to Savings",'April'!I5:I64,Setup!A17)+SUMIFS('May'!F5:F64,'May'!D5:D64,"Added to Savings",'May'!I5:I64,Setup!A17)+SUMIFS('June'!F5:F64,'June'!D5:D64,"Added to Savings",'June'!I5:I64,Setup!A17)+SUMIFS('July'!F5:F64,'July'!D5:D64,"Added to Savings",'July'!I5:I64,Setup!A17)+SUMIFS('August'!F5:F64,'August'!D5:D64,"Added to Savings",'August'!I5:I64,Setup!A17)+SUMIFS('September'!F5:F64,'September'!D5:D64,"Added to Savings",'September'!I5:I64,Setup!A17)+SUMIFS('October'!F5:F64,'October'!D5:D64,"Added to Savings",'October'!I5:I64,Setup!A17)+SUMIFS('November'!F5:F64,'November'!D5:D64,"Added to Savings",'November'!I5:I64,Setup!A17))-(SUMIFS('April'!F5:F64,'April'!G5:G64,Setup!A17)+SUMIFS('May'!F5:F64,'May'!G5:G64,Setup!A17)+SUMIFS('June'!F5:F64,'June'!G5:G64,Setup!A17)+SUMIFS('July'!F5:F64,'July'!G5:G64,Setup!A17)+SUMIFS('August'!F5:F64,'August'!G5:G64,Setup!A17)+SUMIFS('September'!F5:F64,'September'!G5:G64,Setup!A17)+SUMIFS('October'!F5:F64,'October'!G5:G64,Setup!A17)+SUMIFS('November'!F5:F64,'November'!G5:G64,Setup!A17)),"")
A18: =IF(F18<>"",ROW()-4,"") | L18: Fixed Bills Paid | M18: =SUMIF(D5:D255,"Fixed Bills",F5:F255)
A19: =IF(F19<>"",ROW()-4,"") | L19: Food & Dining | M19: =SUMIF(D5:D255,"Food & Dining",F5:F255)
A20: =IF(F20<>"",ROW()-4,"") | L20: Transport | M20: =SUMIF(D5:D255,"Transport & Fuel",F5:F255)
A21: =IF(F21<>"",ROW()-4,"") | L21: Groceries | M21: =SUMIF(D5:D255,"Groceries",F5:F255)
A22: =IF(F22<>"",ROW()-4,"") | L22: Shopping | M22: =SUMIF(D5:D255,"Shopping & Clothing",F5:F255)
A23: =IF(F23<>"",ROW()-4,"") | L23: Entertainment | M23: =SUMIF(D5:D255,"Entertainment & OTT",F5:F255)
A24: =IF(F24<>"",ROW()-4,"") | L24: Investment | M24: =SUMIF(D5:D255,"Investment",F5:F255)
A25: =IF(F25<>"",ROW()-4,"") | L25: Added to Savings | M25: =SUMIF(D5:D255,"Added to Savings",F5:F255)
A26: =IF(F26<>"",ROW()-4,"") | L26: CC Payments | M26: =SUMIF(D5:D255,"Credit Card Payment",F5:F255)
A27: =IF(F27<>"",ROW()-4,"") | L27: Miscellaneous | M27: =SUMIF(D5:D255,"Miscellaneous",F5:F255)
A28: =IF(F28<>"",ROW()-4,"")
A29: =IF(F29<>"",ROW()-4,"")
A30: =IF(F30<>"",ROW()-4,"")
A31: =IF(F31<>"",ROW()-4,"")
A32: =IF(F32<>"",ROW()-4,"")
A33: =IF(F33<>"",ROW()-4,"")
A34: =IF(F34<>"",ROW()-4,"")
A35: =IF(F35<>"",ROW()-4,"")
A36: =IF(F36<>"",ROW()-4,"")
A37: =IF(F37<>"",ROW()-4,"")
A38: =IF(F38<>"",ROW()-4,"")
A39: =IF(F39<>"",ROW()-4,"")
... A255: =IF(F255<>"",ROW()-4,"")
A256: TOTAL EXPENSES THIS MONTH | F256: =SUM(F5:F255)

Sheet December
A1: 📝 DECEMBER — EXPENSE LOG
A2: ℹ️ Date is DateTime. Category dropdown → Sub-category changes automatically. 'Added to Savings' → pick your saving account in Sub-category. CC spend → pick card in 'CC Name'. CC payment → increases card limit.
A4: # | B4: Date & Time | C4: Description | D4: Category | E4: Sub-category | F4: Amount (₹) | G4: Paid From | H4: CC Name | I4: Account | J4: Notes | L4: 📊 December Summary | M4: Amount (₹)
A5: =IF(F5<>"",ROW()-4,"") | L5: Total Expenses | M5: =F256
A6: =IF(F6<>"",ROW()-4,"") | L6: Income This Month | M6: =Income!E12
A7: =IF(F7<>"",ROW()-4,"") | L7: Net This Month | M7: =M6-M5
A8: =IF(F8<>"",ROW()-4,"") | L8: Savings 1 (this month) | M8: =IF(Setup!A13<>"",SUMIFS(F5:F255,D5:D255,"Added to Savings",I5:I255,Setup!A13)-SUMIFS(F5:F255,G5:G255,Setup!A13),"")
A9: =IF(F9<>"",ROW()-4,"") | L9: Savings 1 (balance) | M9: =IF(Setup!A13<>"",Setup!B13+(SUMIFS('April'!F5:F64,'April'!D5:D64,"Added to Savings",'April'!I5:I64,Setup!A13)+SUMIFS('May'!F5:F64,'May'!D5:D64,"Added to Savings",'May'!I5:I64,Setup!A13)+SUMIFS('June'!F5:F64,'June'!D5:D64,"Added to Savings",'June'!I5:I64,Setup!A13)+SUMIFS('July'!F5:F64,'July'!D5:D64,"Added to Savings",'July'!I5:I64,Setup!A13)+SUMIFS('August'!F5:F64,'August'!D5:D64,"Added to Savings",'August'!I5:I64,Setup!A13)+SUMIFS('September'!F5:F64,'September'!D5:D64,"Added to Savings",'September'!I5:I64,Setup!A13)+SUMIFS('October'!F5:F64,'October'!D5:D64,"Added to Savings",'October'!I5:I64,Setup!A13)+SUMIFS('November'!F5:F64,'November'!D5:D64,"Added to Savings",'November'!I5:I64,Setup!A13)+SUMIFS('December'!F5:F64,'December'!D5:D64,"Added to Savings",'December'!I5:I64,Setup!A13))-(SUMIFS('April'!F5:F64,'April'!G5:G64,Setup!A13)+SUMIFS('May'!F5:F64,'May'!G5:G64,Setup!A13)+SUMIFS('June'!F5:F64,'June'!G5:G64,Setup!A13)+SUMIFS('July'!F5:F64,'July'!G5:G64,Setup!A13)+SUMIFS('August'!F5:F64,'August'!G5:G64,Setup!A13)+SUMIFS('September'!F5:F64,'September'!G5:G64,Setup!A13)+SUMIFS('October'!F5:F64,'October'!G5:G64,Setup!A13)+SUMIFS('November'!F5:F64,'November'!G5:G64,Setup!A13)+SUMIFS('December'!F5:F64,'December'!G5:G64,Setup!A13)),"")
A10: =IF(F10<>"",ROW()-4,"") | L10: Savings 2 (this month) | M10: =IF(Setup!A14<>"",SUMIFS(F5:F255,D5:D255,"Added to Savings",I5:I255,Setup!A14)-SUMIFS(F5:F255,G5:G255,Setup!A14),"")
A11: =IF(F11<>"",ROW()-4,"") | L11: Savings 2 (balance) | M11: =IF(Setup!A14<>"",Setup!B14+(SUMIFS('April'!F5:F64,'April'!D5:D64,"Added to Savings",'April'!I5:I64,Setup!A14)+SUMIFS('May'!F5:F64,'May'!D5:D64,"Added to Savings",'May'!I5:I64,Setup!A14)+SUMIFS('June'!F5:F64,'June'!D5:D64,"Added to Savings",'June'!I5:I64,Setup!A14)+SUMIFS('July'!F5:F64,'July'!D5:D64,"Added to Savings",'July'!I5:I64,Setup!A14)+SUMIFS('August'!F5:F64,'August'!D5:D64,"Added to Savings",'August'!I5:I64,Setup!A14)+SUMIFS('September'!F5:F64,'September'!D5:D64,"Added to Savings",'September'!I5:I64,Setup!A14)+SUMIFS('October'!F5:F64,'October'!D5:D64,"Added to Savings",'October'!I5:I64,Setup!A14)+SUMIFS('November'!F5:F64,'November'!D5:D64,"Added to Savings",'November'!I5:I64,Setup!A14)+SUMIFS('December'!F5:F64,'December'!D5:D64,"Added to Savings",'December'!I5:I64,Setup!A14))-(SUMIFS('April'!F5:F64,'April'!G5:G64,Setup!A14)+SUMIFS('May'!F5:F64,'May'!G5:G64,Setup!A14)+SUMIFS('June'!F5:F64,'June'!G5:G64,Setup!A14)+SUMIFS('July'!F5:F64,'July'!G5:G64,Setup!A14)+SUMIFS('August'!F5:F64,'August'!G5:G64,Setup!A14)+SUMIFS('September'!F5:F64,'September'!G5:G64,Setup!A14)+SUMIFS('October'!F5:F64,'October'!G5:G64,Setup!A14)+SUMIFS('November'!F5:F64,'November'!G5:G64,Setup!A14)+SUMIFS('December'!F5:F64,'December'!G5:G64,Setup!A14)),"")
A12: =IF(F12<>"",ROW()-4,"") | L12: Savings 3 (this month) | M12: =IF(Setup!A15<>"",SUMIFS(F5:F255,D5:D255,"Added to Savings",I5:I255,Setup!A15)-SUMIFS(F5:F255,G5:G255,Setup!A15),"")
A13: =IF(F13<>"",ROW()-4,"") | L13: Savings 3 (balance) | M13: =IF(Setup!A15<>"",Setup!B15+(SUMIFS('April'!F5:F64,'April'!D5:D64,"Added to Savings",'April'!I5:I64,Setup!A15)+SUMIFS('May'!F5:F64,'May'!D5:D64,"Added to Savings",'May'!I5:I64,Setup!A15)+SUMIFS('June'!F5:F64,'June'!D5:D64,"Added to Savings",'June'!I5:I64,Setup!A15)+SUMIFS('July'!F5:F64,'July'!D5:D64,"Added to Savings",'July'!I5:I64,Setup!A15)+SUMIFS('August'!F5:F64,'August'!D5:D64,"Added to Savings",'August'!I5:I64,Setup!A15)+SUMIFS('September'!F5:F64,'September'!D5:D64,"Added to Savings",'September'!I5:I64,Setup!A15)+SUMIFS('October'!F5:F64,'October'!D5:D64,"Added to Savings",'October'!I5:I64,Setup!A15)+SUMIFS('November'!F5:F64,'November'!D5:D64,"Added to Savings",'November'!I5:I64,Setup!A15)+SUMIFS('December'!F5:F64,'December'!D5:D64,"Added to Savings",'December'!I5:I64,Setup!A15))-(SUMIFS('April'!F5:F64,'April'!G5:G64,Setup!A15)+SUMIFS('May'!F5:F64,'May'!G5:G64,Setup!A15)+SUMIFS('June'!F5:F64,'June'!G5:G64,Setup!A15)+SUMIFS('July'!F5:F64,'July'!G5:G64,Setup!A15)+SUMIFS('August'!F5:F64,'August'!G5:G64,Setup!A15)+SUMIFS('September'!F5:F64,'September'!G5:G64,Setup!A15)+SUMIFS('October'!F5:F64,'October'!G5:G64,Setup!A15)+SUMIFS('November'!F5:F64,'November'!G5:G64,Setup!A15)+SUMIFS('December'!F5:F64,'December'!G5:G64,Setup!A15)),"")
A14: =IF(F14<>"",ROW()-4,"") | L14: Savings 4 (this month) | M14: =IF(Setup!A16<>"",SUMIFS(F5:F255,D5:D255,"Added to Savings",I5:I255,Setup!A16)-SUMIFS(F5:F255,G5:G255,Setup!A16),"")
A15: =IF(F15<>"",ROW()-4,"") | L15: Savings 4 (balance) | M15: =IF(Setup!A16<>"",Setup!B16+(SUMIFS('April'!F5:F64,'April'!D5:D64,"Added to Savings",'April'!I5:I64,Setup!A16)+SUMIFS('May'!F5:F64,'May'!D5:D64,"Added to Savings",'May'!I5:I64,Setup!A16)+SUMIFS('June'!F5:F64,'June'!D5:D64,"Added to Savings",'June'!I5:I64,Setup!A16)+SUMIFS('July'!F5:F64,'July'!D5:D64,"Added to Savings",'July'!I5:I64,Setup!A16)+SUMIFS('August'!F5:F64,'August'!D5:D64,"Added to Savings",'August'!I5:I64,Setup!A16)+SUMIFS('September'!F5:F64,'September'!D5:D64,"Added to Savings",'September'!I5:I64,Setup!A16)+SUMIFS('October'!F5:F64,'October'!D5:D64,"Added to Savings",'October'!I5:I64,Setup!A16)+SUMIFS('November'!F5:F64,'November'!D5:D64,"Added to Savings",'November'!I5:I64,Setup!A16)+SUMIFS('December'!F5:F64,'December'!D5:D64,"Added to Savings",'December'!I5:I64,Setup!A16))-(SUMIFS('April'!F5:F64,'April'!G5:G64,Setup!A16)+SUMIFS('May'!F5:F64,'May'!G5:G64,Setup!A16)+SUMIFS('June'!F5:F64,'June'!G5:G64,Setup!A16)+SUMIFS('July'!F5:F64,'July'!G5:G64,Setup!A16)+SUMIFS('August'!F5:F64,'August'!G5:G64,Setup!A16)+SUMIFS('September'!F5:F64,'September'!G5:G64,Setup!A16)+SUMIFS('October'!F5:F64,'October'!G5:G64,Setup!A16)+SUMIFS('November'!F5:F64,'November'!G5:G64,Setup!A16)+SUMIFS('December'!F5:F64,'December'!G5:G64,Setup!A16)),"")
A16: =IF(F16<>"",ROW()-4,"") | L16: Savings 5 (this month) | M16: =IF(Setup!A17<>"",SUMIFS(F5:F255,D5:D255,"Added to Savings",I5:I255,Setup!A17)-SUMIFS(F5:F255,G5:G255,Setup!A17),"")
